<?xml version="1.0"?>
<robot name= "3linksrobot">

    <!-- Define the colour to use -->
    <material name="blue">
        <color rgba="0 0 1 1"/>
    </material>

    <link name= "base_link">
        <inertial>
            <origin xyz="0 0 0.1"/>
            <mass value="100.0"/>
            <inertia ixx="0.1" ixy="0.0" ixz="0.0"
                iyy="0.1" iyz="0.0"
                izz="0.1"/>
        </inertial>

        <visual>
            <origin xyz="0 0 0.1"/>
            <geometry>
                <box size= "0.4 0.4 0.2"/>
            </geometry>
        </visual>

        <collision>
            <origin xyz= "0 0 0.1"/>
            <geometry>
                <box size= "0.4 0.4 0.2"/>
            </geometry>
        </collision>

    </link>
    
    <link name= "body_link">
        <inertial>
            <origin xyz="0 0 0.35"/>
            <mass value="10.0"/>
            <inertia ixx="0.1" ixy="0.0" ixz="0.0"
                iyy="0.1" iyz="0.0"
                izz="0.1"/>
        </inertial>

        <visual>
            <origin xyz="0 0 0.35"/>
            <geometry>
                <box size= "0.1 0.1 0.7"/>
            </geometry>
            <material name="blue"/>
        </visual>

        <collision>
            <origin xyz= "0 0 0.35"/>
            <geometry>
                <box size= "0.1 0.1 0.7"/>
            </geometry>
        </collision>

    </link>

    <link name= "top_link">
        <inertial>
            <origin xyz="0.15 0 0.025"/>
            <mass value="5.0"/>
            <inertia ixx="0.1" ixy="0.0" ixz="0.0"
                iyy="0.1" iyz="0.0"
                izz="(1/3)*5*0.3"/>
        </inertial>

        <visual>
            <origin xyz="0.15 0 0.025"/>
            <geometry>
                <box size= "0.3 0.1 0.05"/>
            </geometry>
            <material name="blue"/>
        </visual>

        <collision>
            <origin xyz= "0.15 0 0.025"/>
            <geometry>
                <box size= "0.3 0.1 0.05"/>
            </geometry>
        </collision>
    </link>

    <joint name= "base_to_body" type="fixed">
        <parent link= "base_link"/>
        <child link= "body_link"/>
        <origin xyz = "0 0 0.2"/>
    </joint>

    <joint name= "body_to_top" type="continuous">
        <parent link= "body_link"/>
        <child link= "top_link"/>
        <dynamics damping="0.0" friction= "0.0001"/>

        <origin xyz = "0 0 0.7"/>
        <axis xyz = "0 0 1"/>
 
        <limit effort= "20.0" velocity= "20.0"/>
    </joint>

</robot>
